2025-01-28 15:32:14,426 - app - ERROR - Exception on /api/chat [POST]
Traceback (most recent call last):
  File "/usr/local/python/3.12.1/lib/python3.12/site-packages/flask/app.py", line 1511, in wsgi_app
    response = self.full_dispatch_request()
               ^^^^^^^^^^^^^^^^^^^^^^^^^^^^
  File "/usr/local/python/3.12.1/lib/python3.12/site-packages/flask/app.py", line 919, in full_dispatch_request
    rv = self.handle_user_exception(e)
         ^^^^^^^^^^^^^^^^^^^^^^^^^^^^^
  File "/usr/local/python/3.12.1/lib/python3.12/site-packages/flask/app.py", line 917, in full_dispatch_request
    rv = self.dispatch_request()
         ^^^^^^^^^^^^^^^^^^^^^^^
  File "/usr/local/python/3.12.1/lib/python3.12/site-packages/flask/app.py", line 902, in dispatch_request
    return self.ensure_sync(self.view_functions[rule.endpoint])(**view_args)  # type: ignore[no-any-return]
           ^^^^^^^^^^^^^^^^^^^^^^^^^^^^^^^^^^^^^^^^^^^^^^^^^^^^^^^^^^^^^^^^^
  File "/workspaces/ssuubi-mental-health-bot/app/routes/chat_routes.py", line 24, in chat
    response = response_generator.generate_response(message, context)
               ^^^^^^^^^^^^^^^^^^^^^^^^^^^^^^^^^^^^^^^^^^^^^^^^^^^^^^
  File "/workspaces/ssuubi-mental-health-bot/app/services/response_generator.py", line 14, in generate_response
    analysis = self.sentiment_analyzer.analyze_message(message)
               ^^^^^^^^^^^^^^^^^^^^^^^^^^^^^^^^^^^^^^^^^^^^^^^^
  File "/workspaces/ssuubi-mental-health-bot/app/services/sentiment_analyzer.py", line 14, in analyze_message
    emotion_intensity = self._detect_emotion_intensity(message)
                        ^^^^^^^^^^^^^^^^^^^^^^^^^^^^^^^^^^^^^^^
  File "/workspaces/ssuubi-mental-health-bot/app/services/sentiment_analyzer.py", line 32, in _detect_emotion_intensity
    words = word_tokenize(message.lower())
            ^^^^^^^^^^^^^^^^^^^^^^^^^^^^^^
  File "/usr/local/python/3.12.1/lib/python3.12/site-packages/nltk/tokenize/__init__.py", line 142, in word_tokenize
    sentences = [text] if preserve_line else sent_tokenize(text, language)
                                             ^^^^^^^^^^^^^^^^^^^^^^^^^^^^^
  File "/usr/local/python/3.12.1/lib/python3.12/site-packages/nltk/tokenize/__init__.py", line 119, in sent_tokenize
    tokenizer = _get_punkt_tokenizer(language)
                ^^^^^^^^^^^^^^^^^^^^^^^^^^^^^^
  File "/usr/local/python/3.12.1/lib/python3.12/site-packages/nltk/tokenize/__init__.py", line 105, in _get_punkt_tokenizer
    return PunktTokenizer(language)
           ^^^^^^^^^^^^^^^^^^^^^^^^
  File "/usr/local/python/3.12.1/lib/python3.12/site-packages/nltk/tokenize/punkt.py", line 1744, in __init__
    self.load_lang(lang)
  File "/usr/local/python/3.12.1/lib/python3.12/site-packages/nltk/tokenize/punkt.py", line 1749, in load_lang
    lang_dir = find(f"tokenizers/punkt_tab/{lang}/")
               ^^^^^^^^^^^^^^^^^^^^^^^^^^^^^^^^^^^^^
  File "/usr/local/python/3.12.1/lib/python3.12/site-packages/nltk/data.py", line 579, in find
    raise LookupError(resource_not_found)
LookupError: 
**********************************************************************
  Resource [93mpunkt_tab[0m not found.
  Please use the NLTK Downloader to obtain the resource:

  [31m>>> import nltk
  >>> nltk.download('punkt_tab')
  [0m
  For more information see: https://www.nltk.org/data.html

  Attempted to load [93mtokenizers/punkt_tab/english/[0m

  Searched in:
    - '/home/codespace/nltk_data'
    - '/usr/local/python/3.12.1/nltk_data'
    - '/usr/local/python/3.12.1/share/nltk_data'
    - '/usr/local/python/3.12.1/lib/nltk_data'
    - '/usr/share/nltk_data'
    - '/usr/local/share/nltk_data'
    - '/usr/lib/nltk_data'
    - '/usr/local/lib/nltk_data'
**********************************************************************

2025-01-28 15:35:33,570 - app - ERROR - Exception on /api/chat [POST]
Traceback (most recent call last):
  File "/usr/local/python/3.12.1/lib/python3.12/site-packages/flask/app.py", line 1511, in wsgi_app
    response = self.full_dispatch_request()
               ^^^^^^^^^^^^^^^^^^^^^^^^^^^^
  File "/usr/local/python/3.12.1/lib/python3.12/site-packages/flask/app.py", line 919, in full_dispatch_request
    rv = self.handle_user_exception(e)
         ^^^^^^^^^^^^^^^^^^^^^^^^^^^^^
  File "/usr/local/python/3.12.1/lib/python3.12/site-packages/flask/app.py", line 917, in full_dispatch_request
    rv = self.dispatch_request()
         ^^^^^^^^^^^^^^^^^^^^^^^
  File "/usr/local/python/3.12.1/lib/python3.12/site-packages/flask/app.py", line 902, in dispatch_request
    return self.ensure_sync(self.view_functions[rule.endpoint])(**view_args)  # type: ignore[no-any-return]
           ^^^^^^^^^^^^^^^^^^^^^^^^^^^^^^^^^^^^^^^^^^^^^^^^^^^^^^^^^^^^^^^^^
  File "/workspaces/ssuubi-mental-health-bot/app/routes/chat_routes.py", line 24, in chat
    response = response_generator.generate_response(message, context)
               ^^^^^^^^^^^^^^^^^^^^^^^^^^^^^^^^^^^^^^^^^^^^^^^^^^^^^^
  File "/workspaces/ssuubi-mental-health-bot/app/services/response_generator.py", line 14, in generate_response
    analysis = self.sentiment_analyzer.analyze_message(message)
               ^^^^^^^^^^^^^^^^^^^^^^^^^^^^^^^^^^^^^^^^^^^^^^^^
  File "/workspaces/ssuubi-mental-health-bot/app/services/sentiment_analyzer.py", line 14, in analyze_message
    emotion_intensity = self._detect_emotion_intensity(message)
                        ^^^^^^^^^^^^^^^^^^^^^^^^^^^^^^^^^^^^^^^
  File "/workspaces/ssuubi-mental-health-bot/app/services/sentiment_analyzer.py", line 32, in _detect_emotion_intensity
    words = word_tokenize(message.lower())
            ^^^^^^^^^^^^^^^^^^^^^^^^^^^^^^
  File "/usr/local/python/3.12.1/lib/python3.12/site-packages/nltk/tokenize/__init__.py", line 142, in word_tokenize
    sentences = [text] if preserve_line else sent_tokenize(text, language)
                                             ^^^^^^^^^^^^^^^^^^^^^^^^^^^^^
  File "/usr/local/python/3.12.1/lib/python3.12/site-packages/nltk/tokenize/__init__.py", line 119, in sent_tokenize
    tokenizer = _get_punkt_tokenizer(language)
                ^^^^^^^^^^^^^^^^^^^^^^^^^^^^^^
  File "/usr/local/python/3.12.1/lib/python3.12/site-packages/nltk/tokenize/__init__.py", line 105, in _get_punkt_tokenizer
    return PunktTokenizer(language)
           ^^^^^^^^^^^^^^^^^^^^^^^^
  File "/usr/local/python/3.12.1/lib/python3.12/site-packages/nltk/tokenize/punkt.py", line 1744, in __init__
    self.load_lang(lang)
  File "/usr/local/python/3.12.1/lib/python3.12/site-packages/nltk/tokenize/punkt.py", line 1749, in load_lang
    lang_dir = find(f"tokenizers/punkt_tab/{lang}/")
               ^^^^^^^^^^^^^^^^^^^^^^^^^^^^^^^^^^^^^
  File "/usr/local/python/3.12.1/lib/python3.12/site-packages/nltk/data.py", line 579, in find
    raise LookupError(resource_not_found)
LookupError: 
**********************************************************************
  Resource [93mpunkt_tab[0m not found.
  Please use the NLTK Downloader to obtain the resource:

  [31m>>> import nltk
  >>> nltk.download('punkt_tab')
  [0m
  For more information see: https://www.nltk.org/data.html

  Attempted to load [93mtokenizers/punkt_tab/english/[0m

  Searched in:
    - '/home/codespace/nltk_data'
    - '/usr/local/python/3.12.1/nltk_data'
    - '/usr/local/python/3.12.1/share/nltk_data'
    - '/usr/local/python/3.12.1/lib/nltk_data'
    - '/usr/share/nltk_data'
    - '/usr/local/share/nltk_data'
    - '/usr/lib/nltk_data'
    - '/usr/local/lib/nltk_data'
**********************************************************************

2025-01-28 15:35:43,600 - app - ERROR - Exception on /api/chat [POST]
Traceback (most recent call last):
  File "/usr/local/python/3.12.1/lib/python3.12/site-packages/flask/app.py", line 1511, in wsgi_app
    response = self.full_dispatch_request()
               ^^^^^^^^^^^^^^^^^^^^^^^^^^^^
  File "/usr/local/python/3.12.1/lib/python3.12/site-packages/flask/app.py", line 919, in full_dispatch_request
    rv = self.handle_user_exception(e)
         ^^^^^^^^^^^^^^^^^^^^^^^^^^^^^
  File "/usr/local/python/3.12.1/lib/python3.12/site-packages/flask/app.py", line 917, in full_dispatch_request
    rv = self.dispatch_request()
         ^^^^^^^^^^^^^^^^^^^^^^^
  File "/usr/local/python/3.12.1/lib/python3.12/site-packages/flask/app.py", line 902, in dispatch_request
    return self.ensure_sync(self.view_functions[rule.endpoint])(**view_args)  # type: ignore[no-any-return]
           ^^^^^^^^^^^^^^^^^^^^^^^^^^^^^^^^^^^^^^^^^^^^^^^^^^^^^^^^^^^^^^^^^
  File "/workspaces/ssuubi-mental-health-bot/app/routes/chat_routes.py", line 24, in chat
    response = response_generator.generate_response(message, context)
               ^^^^^^^^^^^^^^^^^^^^^^^^^^^^^^^^^^^^^^^^^^^^^^^^^^^^^^
  File "/workspaces/ssuubi-mental-health-bot/app/services/response_generator.py", line 14, in generate_response
    analysis = self.sentiment_analyzer.analyze_message(message)
               ^^^^^^^^^^^^^^^^^^^^^^^^^^^^^^^^^^^^^^^^^^^^^^^^
  File "/workspaces/ssuubi-mental-health-bot/app/services/sentiment_analyzer.py", line 14, in analyze_message
    emotion_intensity = self._detect_emotion_intensity(message)
                        ^^^^^^^^^^^^^^^^^^^^^^^^^^^^^^^^^^^^^^^
  File "/workspaces/ssuubi-mental-health-bot/app/services/sentiment_analyzer.py", line 32, in _detect_emotion_intensity
    words = word_tokenize(message.lower())
            ^^^^^^^^^^^^^^^^^^^^^^^^^^^^^^
  File "/usr/local/python/3.12.1/lib/python3.12/site-packages/nltk/tokenize/__init__.py", line 142, in word_tokenize
    sentences = [text] if preserve_line else sent_tokenize(text, language)
                                             ^^^^^^^^^^^^^^^^^^^^^^^^^^^^^
  File "/usr/local/python/3.12.1/lib/python3.12/site-packages/nltk/tokenize/__init__.py", line 119, in sent_tokenize
    tokenizer = _get_punkt_tokenizer(language)
                ^^^^^^^^^^^^^^^^^^^^^^^^^^^^^^
  File "/usr/local/python/3.12.1/lib/python3.12/site-packages/nltk/tokenize/__init__.py", line 105, in _get_punkt_tokenizer
    return PunktTokenizer(language)
           ^^^^^^^^^^^^^^^^^^^^^^^^
  File "/usr/local/python/3.12.1/lib/python3.12/site-packages/nltk/tokenize/punkt.py", line 1744, in __init__
    self.load_lang(lang)
  File "/usr/local/python/3.12.1/lib/python3.12/site-packages/nltk/tokenize/punkt.py", line 1749, in load_lang
    lang_dir = find(f"tokenizers/punkt_tab/{lang}/")
               ^^^^^^^^^^^^^^^^^^^^^^^^^^^^^^^^^^^^^
  File "/usr/local/python/3.12.1/lib/python3.12/site-packages/nltk/data.py", line 579, in find
    raise LookupError(resource_not_found)
LookupError: 
**********************************************************************
  Resource [93mpunkt_tab[0m not found.
  Please use the NLTK Downloader to obtain the resource:

  [31m>>> import nltk
  >>> nltk.download('punkt_tab')
  [0m
  For more information see: https://www.nltk.org/data.html

  Attempted to load [93mtokenizers/punkt_tab/english/[0m

  Searched in:
    - '/home/codespace/nltk_data'
    - '/usr/local/python/3.12.1/nltk_data'
    - '/usr/local/python/3.12.1/share/nltk_data'
    - '/usr/local/python/3.12.1/lib/nltk_data'
    - '/usr/share/nltk_data'
    - '/usr/local/share/nltk_data'
    - '/usr/lib/nltk_data'
    - '/usr/local/lib/nltk_data'
**********************************************************************

2025-01-28 15:36:20,432 - app - ERROR - Exception on /api/chat [POST]
Traceback (most recent call last):
  File "/usr/local/python/3.12.1/lib/python3.12/site-packages/flask/app.py", line 1511, in wsgi_app
    response = self.full_dispatch_request()
               ^^^^^^^^^^^^^^^^^^^^^^^^^^^^
  File "/usr/local/python/3.12.1/lib/python3.12/site-packages/flask/app.py", line 919, in full_dispatch_request
    rv = self.handle_user_exception(e)
         ^^^^^^^^^^^^^^^^^^^^^^^^^^^^^
  File "/usr/local/python/3.12.1/lib/python3.12/site-packages/flask/app.py", line 917, in full_dispatch_request
    rv = self.dispatch_request()
         ^^^^^^^^^^^^^^^^^^^^^^^
  File "/usr/local/python/3.12.1/lib/python3.12/site-packages/flask/app.py", line 902, in dispatch_request
    return self.ensure_sync(self.view_functions[rule.endpoint])(**view_args)  # type: ignore[no-any-return]
           ^^^^^^^^^^^^^^^^^^^^^^^^^^^^^^^^^^^^^^^^^^^^^^^^^^^^^^^^^^^^^^^^^
  File "/workspaces/ssuubi-mental-health-bot/app/routes/chat_routes.py", line 24, in chat
    response = response_generator.generate_response(message, context)
               ^^^^^^^^^^^^^^^^^^^^^^^^^^^^^^^^^^^^^^^^^^^^^^^^^^^^^^
  File "/workspaces/ssuubi-mental-health-bot/app/services/response_generator.py", line 14, in generate_response
    analysis = self.sentiment_analyzer.analyze_message(message)
               ^^^^^^^^^^^^^^^^^^^^^^^^^^^^^^^^^^^^^^^^^^^^^^^^
  File "/workspaces/ssuubi-mental-health-bot/app/services/sentiment_analyzer.py", line 14, in analyze_message
    emotion_intensity = self._detect_emotion_intensity(message)
                        ^^^^^^^^^^^^^^^^^^^^^^^^^^^^^^^^^^^^^^^
  File "/workspaces/ssuubi-mental-health-bot/app/services/sentiment_analyzer.py", line 32, in _detect_emotion_intensity
    words = word_tokenize(message.lower())
            ^^^^^^^^^^^^^^^^^^^^^^^^^^^^^^
  File "/usr/local/python/3.12.1/lib/python3.12/site-packages/nltk/tokenize/__init__.py", line 142, in word_tokenize
    sentences = [text] if preserve_line else sent_tokenize(text, language)
                                             ^^^^^^^^^^^^^^^^^^^^^^^^^^^^^
  File "/usr/local/python/3.12.1/lib/python3.12/site-packages/nltk/tokenize/__init__.py", line 119, in sent_tokenize
    tokenizer = _get_punkt_tokenizer(language)
                ^^^^^^^^^^^^^^^^^^^^^^^^^^^^^^
  File "/usr/local/python/3.12.1/lib/python3.12/site-packages/nltk/tokenize/__init__.py", line 105, in _get_punkt_tokenizer
    return PunktTokenizer(language)
           ^^^^^^^^^^^^^^^^^^^^^^^^
  File "/usr/local/python/3.12.1/lib/python3.12/site-packages/nltk/tokenize/punkt.py", line 1744, in __init__
    self.load_lang(lang)
  File "/usr/local/python/3.12.1/lib/python3.12/site-packages/nltk/tokenize/punkt.py", line 1749, in load_lang
    lang_dir = find(f"tokenizers/punkt_tab/{lang}/")
               ^^^^^^^^^^^^^^^^^^^^^^^^^^^^^^^^^^^^^
  File "/usr/local/python/3.12.1/lib/python3.12/site-packages/nltk/data.py", line 579, in find
    raise LookupError(resource_not_found)
LookupError: 
**********************************************************************
  Resource [93mpunkt_tab[0m not found.
  Please use the NLTK Downloader to obtain the resource:

  [31m>>> import nltk
  >>> nltk.download('punkt_tab')
  [0m
  For more information see: https://www.nltk.org/data.html

  Attempted to load [93mtokenizers/punkt_tab/english/[0m

  Searched in:
    - '/home/codespace/nltk_data'
    - '/usr/local/python/3.12.1/nltk_data'
    - '/usr/local/python/3.12.1/share/nltk_data'
    - '/usr/local/python/3.12.1/lib/nltk_data'
    - '/usr/share/nltk_data'
    - '/usr/local/share/nltk_data'
    - '/usr/lib/nltk_data'
    - '/usr/local/lib/nltk_data'
**********************************************************************

2025-01-28 20:51:32,062 - app.routes.chat_routes - INFO - Creating new session: demo-session
2025-01-28 20:58:34,560 - app.routes.chat_routes - INFO - Creating new session: demo-session
2025-01-28 20:58:34,659 - app.routes.chat_routes - ERROR - Invalid response format from response generator
2025-01-28 20:58:41,621 - app.routes.chat_routes - ERROR - Invalid response format from response generator
2025-01-28 21:08:08,398 - app.routes.chat_routes - INFO - Creating new conversation handler for session: demo-session
2025-01-28 21:22:19,397 - app.routes.chat_routes - INFO - Creating new conversation handler for session: demo-session
2025-01-28 21:30:24,831 - app.routes.chat_routes - INFO - Creating new conversation handler for session: demo-session
2025-01-28 21:30:24,837 - app.routes.chat_routes - ERROR - Error in chat endpoint: 'CrisisHandler' object has no attribute 'is_crisis_message'
2025-01-28 21:30:24,838 - app.routes.chat_routes - ERROR - Traceback (most recent call last):
  File "/workspaces/ssuubi-mental-health-bot/app/routes/chat_routes.py", line 49, in chat
    response_data = _process_message(handler, message)
                    ^^^^^^^^^^^^^^^^^^^^^^^^^^^^^^^^^^
  File "/workspaces/ssuubi-mental-health-bot/app/routes/chat_routes.py", line 71, in _process_message
    response = handler.generate_response(message)
               ^^^^^^^^^^^^^^^^^^^^^^^^^^^^^^^^^^
  File "/workspaces/ssuubi-mental-health-bot/app/services/conversation_handler.py", line 16, in generate_response
    if self.crisis_handler.is_crisis_message(message):
       ^^^^^^^^^^^^^^^^^^^^^^^^^^^^^^^^^^^^^
AttributeError: 'CrisisHandler' object has no attribute 'is_crisis_message'. Did you mean: 'analyze_crisis_message'?

2025-01-28 21:35:37,689 - app.routes.chat_routes - INFO - Creating new conversation handler for session: demo-session
2025-01-28 21:35:37,692 - app.routes.chat_routes - ERROR - Error in chat endpoint: type object 'MessageIntent' has no attribute 'STRESS'
2025-01-28 21:35:37,694 - app.routes.chat_routes - ERROR - Traceback (most recent call last):
  File "/workspaces/ssuubi-mental-health-bot/app/routes/chat_routes.py", line 46, in chat
    handler = _get_or_create_handler(session_id)
              ^^^^^^^^^^^^^^^^^^^^^^^^^^^^^^^^^^
  File "/workspaces/ssuubi-mental-health-bot/app/routes/chat_routes.py", line 65, in _get_or_create_handler
    conversation_handlers[session_id] = ConversationHandler()
                                        ^^^^^^^^^^^^^^^^^^^^^
  File "/workspaces/ssuubi-mental-health-bot/app/services/conversation_handler.py", line 10, in __init__
    self.analyzer = MessageAnalyzer()
                    ^^^^^^^^^^^^^^^^^
  File "/workspaces/ssuubi-mental-health-bot/app/services/message_analyzer.py", line 9, in __init__
    self.patterns = get_patterns()
                    ^^^^^^^^^^^^^^
  File "/workspaces/ssuubi-mental-health-bot/app/services/patterns.py", line 153, in get_patterns
    intent=MessageIntent.STRESS,
           ^^^^^^^^^^^^^^^^^^^^
AttributeError: type object 'MessageIntent' has no attribute 'STRESS'

2025-01-28 21:38:49,954 - app.routes.chat_routes - INFO - Creating new conversation handler for session: demo-session
2025-04-19 20:50:07,035 - app.routes.chat_routes - INFO - Creating new conversation handler for session: demo-session
2025-04-19 22:31:10,397 - app.routes.chat_routes - INFO - Creating new conversation handler for session: demo-session
2025-04-19 22:37:41,380 - app.routes.chat_routes - INFO - Creating new conversation handler for session: demo-session
2025-04-19 23:21:05,516 - app.routes.chat_routes - INFO - Creating new conversation handler for session: demo-session
2025-04-19 23:21:15,921 - app.services.response_generator - WARNING - mental_health_responses.json not found, using empty responses
2025-04-19 23:21:24,732 - app.routes.chat_routes - ERROR - Error in chat endpoint: ConversationHandler.generate_response() missing 2 required positional arguments: 'session_id' and 'user_id'
2025-04-19 23:21:24,732 - app.routes.chat_routes - ERROR - Traceback (most recent call last):
  File "/workspaces/ssuubi-mental-health-bot/app/routes/chat_routes.py", line 49, in chat
    response_data = _process_message(handler, message)
                    ^^^^^^^^^^^^^^^^^^^^^^^^^^^^^^^^^^
  File "/workspaces/ssuubi-mental-health-bot/app/routes/chat_routes.py", line 71, in _process_message
    response = handler.generate_response(message)
               ^^^^^^^^^^^^^^^^^^^^^^^^^^^^^^^^^^
TypeError: ConversationHandler.generate_response() missing 2 required positional arguments: 'session_id' and 'user_id'

2025-04-19 23:21:39,312 - app.routes.chat_routes - ERROR - Error in chat endpoint: ConversationHandler.generate_response() missing 2 required positional arguments: 'session_id' and 'user_id'
2025-04-19 23:21:39,313 - app.routes.chat_routes - ERROR - Traceback (most recent call last):
  File "/workspaces/ssuubi-mental-health-bot/app/routes/chat_routes.py", line 49, in chat
    response_data = _process_message(handler, message)
                    ^^^^^^^^^^^^^^^^^^^^^^^^^^^^^^^^^^
  File "/workspaces/ssuubi-mental-health-bot/app/routes/chat_routes.py", line 71, in _process_message
    response = handler.generate_response(message)
               ^^^^^^^^^^^^^^^^^^^^^^^^^^^^^^^^^^
TypeError: ConversationHandler.generate_response() missing 2 required positional arguments: 'session_id' and 'user_id'

2025-04-19 23:21:46,716 - app.routes.chat_routes - ERROR - Error in chat endpoint: ConversationHandler.generate_response() missing 2 required positional arguments: 'session_id' and 'user_id'
2025-04-19 23:21:46,716 - app.routes.chat_routes - ERROR - Traceback (most recent call last):
  File "/workspaces/ssuubi-mental-health-bot/app/routes/chat_routes.py", line 49, in chat
    response_data = _process_message(handler, message)
                    ^^^^^^^^^^^^^^^^^^^^^^^^^^^^^^^^^^
  File "/workspaces/ssuubi-mental-health-bot/app/routes/chat_routes.py", line 71, in _process_message
    response = handler.generate_response(message)
               ^^^^^^^^^^^^^^^^^^^^^^^^^^^^^^^^^^
TypeError: ConversationHandler.generate_response() missing 2 required positional arguments: 'session_id' and 'user_id'

2025-04-19 23:33:05,417 - app.routes.chat_routes - INFO - Creating new conversation handler for session: demo-session
2025-04-19 23:33:07,701 - app.services.response_generator - WARNING - mental_health_responses.json not found, using empty responses
2025-04-19 23:33:11,250 - app.services.conversation_handler - ERROR - Error in conversation handler: Session.__init__() takes 2 positional arguments but 3 were given
2025-04-19 23:33:11,251 - app.routes.chat_routes - ERROR - Error in chat endpoint: cannot access local variable 'original_message' where it is not associated with a value
2025-04-19 23:33:11,252 - app.routes.chat_routes - ERROR - Traceback (most recent call last):
  File "/workspaces/ssuubi-mental-health-bot/app/services/conversation_handler.py", line 59, in generate_response
    self.create_session(session_id, user_id)
  File "/workspaces/ssuubi-mental-health-bot/app/services/conversation_handler.py", line 28, in create_session
    self.sessions[session_id] = Session(session_id, user_id)
                                ^^^^^^^^^^^^^^^^^^^^^^^^^^^^
TypeError: Session.__init__() takes 2 positional arguments but 3 were given

During handling of the above exception, another exception occurred:

Traceback (most recent call last):
  File "/workspaces/ssuubi-mental-health-bot/app/routes/chat_routes.py", line 51, in chat
    response_data = _process_message(handler, message, session_id, user_id, language)
                    ^^^^^^^^^^^^^^^^^^^^^^^^^^^^^^^^^^^^^^^^^^^^^^^^^^^^^^^^^^^^^^^^^
  File "/workspaces/ssuubi-mental-health-bot/app/routes/chat_routes.py", line 73, in _process_message
    response = handler.generate_response(message, session_id, user_id, language)
               ^^^^^^^^^^^^^^^^^^^^^^^^^^^^^^^^^^^^^^^^^^^^^^^^^^^^^^^^^^^^^^^^^
  File "/workspaces/ssuubi-mental-health-bot/app/services/conversation_handler.py", line 123, in generate_response
    self._update_session(session_id, original_message, fallback)
                                     ^^^^^^^^^^^^^^^^
UnboundLocalError: cannot access local variable 'original_message' where it is not associated with a value

2025-04-19 23:49:07,506 - app.routes.chat_routes - INFO - Creating new conversation handler for session: demo-session
2025-04-19 23:49:10,313 - app.services.response_generator - WARNING - therapeutic_responses.json not found, using empty responses
2025-04-19 23:49:14,033 - app.services.conversation_handler - ERROR - Failed to create session demo-session: ConversationContext.update_context() got an unexpected keyword argument 'emotional_state'
2025-04-19 23:49:14,033 - app.services.conversation_handler - ERROR - Error in conversation handler: ConversationContext.update_context() got an unexpected keyword argument 'emotional_state'
2025-04-19 23:49:44,073 - app.routes.chat_routes - ERROR - Error in chat endpoint: localhost:27017: [Errno 111] Connection refused (configured timeouts: socketTimeoutMS: 20000.0ms, connectTimeoutMS: 20000.0ms), Timeout: 30s, Topology Description: <TopologyDescription id: 6804367aaaab9470ef8e1e91, topology_type: Unknown, servers: [<ServerDescription ('localhost', 27017) server_type: Unknown, rtt: None, error=AutoReconnect('localhost:27017: [Errno 111] Connection refused (configured timeouts: socketTimeoutMS: 20000.0ms, connectTimeoutMS: 20000.0ms)')>]>
2025-04-19 23:49:44,079 - app.routes.chat_routes - ERROR - Traceback (most recent call last):
  File "/workspaces/ssuubi-mental-health-bot/app/routes/chat_routes.py", line 51, in chat
    response_data = _process_message(handler, message, session_id, user_id, language)
                    ^^^^^^^^^^^^^^^^^^^^^^^^^^^^^^^^^^^^^^^^^^^^^^^^^^^^^^^^^^^^^^^^^
  File "/workspaces/ssuubi-mental-health-bot/app/routes/chat_routes.py", line 76, in _process_message
    context = handler.context.get_context(user_id)
              ^^^^^^^^^^^^^^^^^^^^^^^^^^^^^^^^^^^^
  File "/workspaces/ssuubi-mental-health-bot/app/services/context.py", line 29, in get_context
    context = self.context_collection.find_one({'user_id': user_id})
              ^^^^^^^^^^^^^^^^^^^^^^^^^^^^^^^^^^^^^^^^^^^^^^^^^^^^^^
  File "/usr/local/python/3.12.1/lib/python3.12/site-packages/pymongo/synchronous/collection.py", line 1730, in find_one
    for result in cursor.limit(-1):
  File "/usr/local/python/3.12.1/lib/python3.12/site-packages/pymongo/synchronous/cursor.py", line 1281, in __next__
    return self.next()
           ^^^^^^^^^^^
  File "/usr/local/python/3.12.1/lib/python3.12/site-packages/pymongo/synchronous/cursor.py", line 1257, in next
    if len(self._data) or self._refresh():
                          ^^^^^^^^^^^^^^^
  File "/usr/local/python/3.12.1/lib/python3.12/site-packages/pymongo/synchronous/cursor.py", line 1205, in _refresh
    self._send_message(q)
  File "/usr/local/python/3.12.1/lib/python3.12/site-packages/pymongo/synchronous/cursor.py", line 1100, in _send_message
    response = client._run_operation(
               ^^^^^^^^^^^^^^^^^^^^^^
  File "/usr/local/python/3.12.1/lib/python3.12/site-packages/pymongo/_csot.py", line 119, in csot_wrapper
    return func(self, *args, **kwargs)
           ^^^^^^^^^^^^^^^^^^^^^^^^^^^
  File "/usr/local/python/3.12.1/lib/python3.12/site-packages/pymongo/synchronous/mongo_client.py", line 1754, in _run_operation
    return self._retryable_read(
           ^^^^^^^^^^^^^^^^^^^^^
  File "/usr/local/python/3.12.1/lib/python3.12/site-packages/pymongo/synchronous/mongo_client.py", line 1863, in _retryable_read
    return self._retry_internal(
           ^^^^^^^^^^^^^^^^^^^^^
  File "/usr/local/python/3.12.1/lib/python3.12/site-packages/pymongo/_csot.py", line 119, in csot_wrapper
    return func(self, *args, **kwargs)
           ^^^^^^^^^^^^^^^^^^^^^^^^^^^
  File "/usr/local/python/3.12.1/lib/python3.12/site-packages/pymongo/synchronous/mongo_client.py", line 1830, in _retry_internal
    ).run()
      ^^^^^
  File "/usr/local/python/3.12.1/lib/python3.12/site-packages/pymongo/synchronous/mongo_client.py", line 2554, in run
    return self._read() if self._is_read else self._write()
           ^^^^^^^^^^^^
  File "/usr/local/python/3.12.1/lib/python3.12/site-packages/pymongo/synchronous/mongo_client.py", line 2689, in _read
    self._server = self._get_server()
                   ^^^^^^^^^^^^^^^^^^
  File "/usr/local/python/3.12.1/lib/python3.12/site-packages/pymongo/synchronous/mongo_client.py", line 2645, in _get_server
    return self._client._select_server(
           ^^^^^^^^^^^^^^^^^^^^^^^^^^^^
  File "/usr/local/python/3.12.1/lib/python3.12/site-packages/pymongo/synchronous/mongo_client.py", line 1649, in _select_server
    server = topology.select_server(
             ^^^^^^^^^^^^^^^^^^^^^^^
  File "/usr/local/python/3.12.1/lib/python3.12/site-packages/pymongo/synchronous/topology.py", line 398, in select_server
    server = self._select_server(
             ^^^^^^^^^^^^^^^^^^^^
  File "/usr/local/python/3.12.1/lib/python3.12/site-packages/pymongo/synchronous/topology.py", line 376, in _select_server
    servers = self.select_servers(
              ^^^^^^^^^^^^^^^^^^^^
  File "/usr/local/python/3.12.1/lib/python3.12/site-packages/pymongo/synchronous/topology.py", line 283, in select_servers
    server_descriptions = self._select_servers_loop(
                          ^^^^^^^^^^^^^^^^^^^^^^^^^^
  File "/usr/local/python/3.12.1/lib/python3.12/site-packages/pymongo/synchronous/topology.py", line 333, in _select_servers_loop
    raise ServerSelectionTimeoutError(
pymongo.errors.ServerSelectionTimeoutError: localhost:27017: [Errno 111] Connection refused (configured timeouts: socketTimeoutMS: 20000.0ms, connectTimeoutMS: 20000.0ms), Timeout: 30s, Topology Description: <TopologyDescription id: 6804367aaaab9470ef8e1e91, topology_type: Unknown, servers: [<ServerDescription ('localhost', 27017) server_type: Unknown, rtt: None, error=AutoReconnect('localhost:27017: [Errno 111] Connection refused (configured timeouts: socketTimeoutMS: 20000.0ms, connectTimeoutMS: 20000.0ms)')>]>

2025-04-20 00:22:03,804 - app.routes.chat_routes - INFO - Creating new conversation handler for session: demo-session
2025-04-20 00:22:06,161 - app.services.response_generator - WARNING - mental_health_responses.json not found, using empty responses
2025-04-20 00:22:14,952 - app.services.context - WARNING - MongoDB connection failed: localhost:27017: [Errno 111] Connection refused (configured timeouts: socketTimeoutMS: 20000.0ms, connectTimeoutMS: 20000.0ms), Timeout: 5.0s, Topology Description: <TopologyDescription id: 68043e317e60e60b0b587e93, topology_type: Unknown, servers: [<ServerDescription ('localhost', 27017) server_type: Unknown, rtt: None, error=AutoReconnect('localhost:27017: [Errno 111] Connection refused (configured timeouts: socketTimeoutMS: 20000.0ms, connectTimeoutMS: 20000.0ms)')>]>. Using in-memory storage.
2025-04-20 00:22:14,958 - app.services.conversation_handler - ERROR - Failed to create session demo-session: module 'pymongo' has no attribute 'datetime'
2025-04-20 00:22:14,958 - app.services.conversation_handler - ERROR - Error in conversation handler: module 'pymongo' has no attribute 'datetime'
2025-04-20 00:22:14,959 - app.routes.chat_routes - ERROR - Error in chat endpoint: 'previous_intent'
2025-04-20 00:22:14,959 - app.routes.chat_routes - ERROR - Traceback (most recent call last):
  File "/workspaces/ssuubi-mental-health-bot/app/routes/chat_routes.py", line 51, in chat
    response_data = _process_message(handler, message, session_id, user_id, language)
                    ^^^^^^^^^^^^^^^^^^^^^^^^^^^^^^^^^^^^^^^^^^^^^^^^^^^^^^^^^^^^^^^^^
  File "/workspaces/ssuubi-mental-health-bot/app/routes/chat_routes.py", line 85, in _process_message
    "previous_intent": context["previous_intent"].value if context["previous_intent"] else None
                                                           ~~~~~~~^^^^^^^^^^^^^^^^^^^
KeyError: 'previous_intent'

2025-04-20 00:23:52,151 - app.routes.chat_routes - INFO - Creating new conversation handler for session: demo-session
2025-04-20 00:23:54,490 - app.services.response_generator - WARNING - mental_health_responses.json not found, using empty responses
2025-04-20 00:24:03,229 - app.services.context - WARNING - MongoDB connection failed: localhost:27017: [Errno 111] Connection refused (configured timeouts: socketTimeoutMS: 20000.0ms, connectTimeoutMS: 20000.0ms), Timeout: 5.0s, Topology Description: <TopologyDescription id: 68043e9e57628f3870d216ef, topology_type: Unknown, servers: [<ServerDescription ('localhost', 27017) server_type: Unknown, rtt: None, error=AutoReconnect('localhost:27017: [Errno 111] Connection refused (configured timeouts: socketTimeoutMS: 20000.0ms, connectTimeoutMS: 20000.0ms)')>]>. Using in-memory storage.
2025-04-20 00:24:03,235 - app.services.conversation_handler - ERROR - Failed to create session demo-session: module 'pymongo' has no attribute 'datetime'
2025-04-20 00:24:03,235 - app.services.conversation_handler - ERROR - Error in conversation handler: module 'pymongo' has no attribute 'datetime'
2025-04-20 00:24:03,235 - app.routes.chat_routes - ERROR - Error in chat endpoint: 'previous_intent'
2025-04-20 00:24:03,236 - app.routes.chat_routes - ERROR - Traceback (most recent call last):
  File "/workspaces/ssuubi-mental-health-bot/app/routes/chat_routes.py", line 51, in chat
    response_data = _process_message(handler, message, session_id, user_id, language)
                    ^^^^^^^^^^^^^^^^^^^^^^^^^^^^^^^^^^^^^^^^^^^^^^^^^^^^^^^^^^^^^^^^^
  File "/workspaces/ssuubi-mental-health-bot/app/routes/chat_routes.py", line 85, in _process_message
    "previous_intent": context["previous_intent"].value if context["previous_intent"] else None
                                                           ~~~~~~~^^^^^^^^^^^^^^^^^^^
KeyError: 'previous_intent'

